[2024-09-14 18:40:36,757: ERROR/MainProcess] consumer: Cannot connect to redis://127.0.0.1:6379/3: Error 111 connecting to 127.0.0.1:6379. Connection refused..
Trying again in 2.00 seconds...

[2024-09-14 18:40:37,433: ERROR/MainProcess] consumer: Cannot connect to redis://127.0.0.1:6379/3: Error 111 connecting to 127.0.0.1:6379. Connection refused..
Trying again in 2.00 seconds...

[2024-09-14 18:40:38,110: ERROR/MainProcess] consumer: Cannot connect to redis://127.0.0.1:6379/3: Error 111 connecting to 127.0.0.1:6379. Connection refused..
Trying again in 2.00 seconds...

[2024-09-14 18:40:38,760: ERROR/MainProcess] consumer: Cannot connect to redis://127.0.0.1:6379/3: Error 111 connecting to 127.0.0.1:6379. Connection refused..
Trying again in 4.00 seconds...

[2024-09-14 18:40:39,435: ERROR/MainProcess] consumer: Cannot connect to redis://127.0.0.1:6379/3: Error 111 connecting to 127.0.0.1:6379. Connection refused..
Trying again in 4.00 seconds...

[2024-09-14 18:40:40,113: ERROR/MainProcess] consumer: Cannot connect to redis://127.0.0.1:6379/3: Error 111 connecting to 127.0.0.1:6379. Connection refused..
Trying again in 4.00 seconds...

[2024-09-14 18:40:42,764: ERROR/MainProcess] consumer: Cannot connect to redis://127.0.0.1:6379/3: Error 111 connecting to 127.0.0.1:6379. Connection refused..
Trying again in 6.00 seconds...

[2024-09-14 18:40:43,440: ERROR/MainProcess] consumer: Cannot connect to redis://127.0.0.1:6379/3: Error 111 connecting to 127.0.0.1:6379. Connection refused..
Trying again in 6.00 seconds...

[2024-09-14 18:40:44,117: ERROR/MainProcess] consumer: Cannot connect to redis://127.0.0.1:6379/3: Error 111 connecting to 127.0.0.1:6379. Connection refused..
Trying again in 6.00 seconds...

[2024-09-14 18:40:48,770: ERROR/MainProcess] consumer: Cannot connect to redis://127.0.0.1:6379/3: Error 111 connecting to 127.0.0.1:6379. Connection refused..
Trying again in 8.00 seconds...

[2024-09-14 18:40:49,444: ERROR/MainProcess] consumer: Cannot connect to redis://127.0.0.1:6379/3: Error 111 connecting to 127.0.0.1:6379. Connection refused..
Trying again in 8.00 seconds...

[2024-09-14 18:40:50,123: ERROR/MainProcess] consumer: Cannot connect to redis://127.0.0.1:6379/3: Error 111 connecting to 127.0.0.1:6379. Connection refused..
Trying again in 8.00 seconds...

[2024-09-14 18:40:56,778: ERROR/MainProcess] consumer: Cannot connect to redis://127.0.0.1:6379/3: Error 111 connecting to 127.0.0.1:6379. Connection refused..
Trying again in 10.00 seconds...

[2024-09-14 18:40:57,452: ERROR/MainProcess] consumer: Cannot connect to redis://127.0.0.1:6379/3: Error 111 connecting to 127.0.0.1:6379. Connection refused..
Trying again in 10.00 seconds...

[2024-09-14 18:40:58,131: ERROR/MainProcess] consumer: Cannot connect to redis://127.0.0.1:6379/3: Error 111 connecting to 127.0.0.1:6379. Connection refused..
Trying again in 10.00 seconds...

[2024-09-14 18:41:06,788: ERROR/MainProcess] consumer: Cannot connect to redis://127.0.0.1:6379/3: Error 111 connecting to 127.0.0.1:6379. Connection refused..
Trying again in 12.00 seconds...

[2024-09-14 18:41:07,462: ERROR/MainProcess] consumer: Cannot connect to redis://127.0.0.1:6379/3: Error 111 connecting to 127.0.0.1:6379. Connection refused..
Trying again in 12.00 seconds...

[2024-09-14 18:41:08,141: ERROR/MainProcess] consumer: Cannot connect to redis://127.0.0.1:6379/3: Error 111 connecting to 127.0.0.1:6379. Connection refused..
Trying again in 12.00 seconds...

[2024-09-14 18:41:18,821: ERROR/MainProcess] consumer: Cannot connect to redis://127.0.0.1:6379/3: Error 111 connecting to 127.0.0.1:6379. Connection refused..
Trying again in 14.00 seconds...

[2024-09-14 18:41:19,474: ERROR/MainProcess] consumer: Cannot connect to redis://127.0.0.1:6379/3: Error 111 connecting to 127.0.0.1:6379. Connection refused..
Trying again in 14.00 seconds...

[2024-09-14 18:41:20,153: ERROR/MainProcess] consumer: Cannot connect to redis://127.0.0.1:6379/3: Error 111 connecting to 127.0.0.1:6379. Connection refused..
Trying again in 14.00 seconds...

[2024-09-14 18:41:32,833: ERROR/MainProcess] consumer: Cannot connect to redis://127.0.0.1:6379/3: Error 111 connecting to 127.0.0.1:6379. Connection refused..
Trying again in 16.00 seconds...

[2024-09-14 18:41:33,485: ERROR/MainProcess] consumer: Cannot connect to redis://127.0.0.1:6379/3: Error 111 connecting to 127.0.0.1:6379. Connection refused..
Trying again in 16.00 seconds...

[2024-09-14 18:41:34,166: ERROR/MainProcess] consumer: Cannot connect to redis://127.0.0.1:6379/3: Error 111 connecting to 127.0.0.1:6379. Connection refused..
Trying again in 16.00 seconds...

[2024-09-14 18:41:47,455: ERROR/MainProcess] consumer: Cannot connect to redis://127.0.0.1:6379/3: Error 111 connecting to 127.0.0.1:6379. Connection refused..
Trying again in 2.00 seconds...

[2024-09-14 18:41:49,457: ERROR/MainProcess] consumer: Cannot connect to redis://127.0.0.1:6379/3: Error 111 connecting to 127.0.0.1:6379. Connection refused..
Trying again in 4.00 seconds...

[2024-09-14 18:41:50,359: ERROR/MainProcess] consumer: Cannot connect to redis://127.0.0.1:6379/3: Error 111 connecting to 127.0.0.1:6379. Connection refused..
Trying again in 2.00 seconds...

[2024-09-14 18:41:52,362: ERROR/MainProcess] consumer: Cannot connect to redis://127.0.0.1:6379/3: Error 111 connecting to 127.0.0.1:6379. Connection refused..
Trying again in 4.00 seconds...

[2024-09-14 18:41:52,633: ERROR/MainProcess] consumer: Cannot connect to redis://127.0.0.1:6379/3: Error 111 connecting to 127.0.0.1:6379. Connection refused..
Trying again in 2.00 seconds...

[2024-09-14 18:41:53,461: ERROR/MainProcess] consumer: Cannot connect to redis://127.0.0.1:6379/3: Error 111 connecting to 127.0.0.1:6379. Connection refused..
Trying again in 6.00 seconds...

[2024-09-14 18:41:54,635: ERROR/MainProcess] consumer: Cannot connect to redis://127.0.0.1:6379/3: Error 111 connecting to 127.0.0.1:6379. Connection refused..
Trying again in 4.00 seconds...

[2024-09-14 18:41:56,366: ERROR/MainProcess] consumer: Cannot connect to redis://127.0.0.1:6379/3: Error 111 connecting to 127.0.0.1:6379. Connection refused..
Trying again in 6.00 seconds...

[2024-09-14 18:41:58,639: ERROR/MainProcess] consumer: Cannot connect to redis://127.0.0.1:6379/3: Error 111 connecting to 127.0.0.1:6379. Connection refused..
Trying again in 6.00 seconds...

[2024-09-14 18:41:59,467: ERROR/MainProcess] consumer: Cannot connect to redis://127.0.0.1:6379/3: Error 111 connecting to 127.0.0.1:6379. Connection refused..
Trying again in 8.00 seconds...

[2024-09-14 18:42:02,374: INFO/MainProcess] Connected to redis://127.0.0.1:6379/3
[2024-09-14 18:42:02,380: INFO/MainProcess] mingle: searching for neighbors
[2024-09-14 18:42:03,393: INFO/MainProcess] mingle: all alone
[2024-09-14 18:42:03,405: WARNING/MainProcess] /workspace/Python/py3/lib/python3.8/site-packages/celery/fixups/django.py:202: UserWarning: Using settings.DEBUG leads to a memory leak, never use this setting in production environments!
  warnings.warn('Using settings.DEBUG leads to a memory leak, never '
[2024-09-14 18:42:03,405: INFO/MainProcess] celery3@ws-beejpv-0 ready.
[2024-09-14 18:42:04,647: INFO/MainProcess] Connected to redis://127.0.0.1:6379/3
[2024-09-14 18:42:04,653: INFO/MainProcess] mingle: searching for neighbors
[2024-09-14 18:42:04,665: INFO/MainProcess] sync with celery1@ws-beejpv-0
[2024-09-14 18:42:05,667: INFO/MainProcess] mingle: sync with 1 nodes
[2024-09-14 18:42:05,668: INFO/MainProcess] mingle: sync complete
[2024-09-14 18:42:05,674: WARNING/MainProcess] /workspace/Python/py3/lib/python3.8/site-packages/celery/fixups/django.py:202: UserWarning: Using settings.DEBUG leads to a memory leak, never use this setting in production environments!
  warnings.warn('Using settings.DEBUG leads to a memory leak, never '
[2024-09-14 18:42:05,674: INFO/MainProcess] celery1@ws-beejpv-0 ready.
[2024-09-14 18:42:07,476: INFO/MainProcess] Connected to redis://127.0.0.1:6379/3
[2024-09-14 18:42:07,484: INFO/MainProcess] mingle: searching for neighbors
[2024-09-14 18:42:07,496: INFO/MainProcess] sync with celery2@ws-beejpv-0
[2024-09-14 18:42:07,496: INFO/MainProcess] sync with celery2@ws-beejpv-0
[2024-09-14 18:42:08,499: INFO/MainProcess] mingle: sync with 2 nodes
[2024-09-14 18:42:08,499: INFO/MainProcess] mingle: sync complete
[2024-09-14 18:42:08,506: WARNING/MainProcess] /workspace/Python/py3/lib/python3.8/site-packages/celery/fixups/django.py:202: UserWarning: Using settings.DEBUG leads to a memory leak, never use this setting in production environments!
  warnings.warn('Using settings.DEBUG leads to a memory leak, never '
[2024-09-14 18:42:08,506: INFO/MainProcess] celery2@ws-beejpv-0 ready.
[2024-09-14 18:42:34,031: INFO/MainProcess] Received task: myCelery.ansiblePlayBook[6d8302b3-f5c4-418b-b4bd-41cc2aea37bc]  
[2024-09-14 18:42:34,184: WARNING/ForkPoolWorker-3] PLAY [localhost]
[2024-09-14 18:42:34,235: WARNING/ForkPoolWorker-3] [34mÂÜôÂÖ•RedisÔºö{"host": "localhost", "result": {"msg": "nihao", "......[0m
[2024-09-14 18:42:34,256: WARNING/ForkPoolWorker-3] ÊâßË°åÊàêÂäü notice from on_success
[2024-09-14 18:42:34,256: INFO/MainProcess] Received task: myCelery.syncAnsibleResult[8c307a9d-9bc0-4743-9d46-e1a69dc15d43]  
[2024-09-14 18:42:34,256: INFO/ForkPoolWorker-3] Task myCelery.ansiblePlayBook[6d8302b3-f5c4-418b-b4bd-41cc2aea37bc] succeeded in 0.22377893328666687s: 'success'
[2024-09-14 18:42:34,258: INFO/ForkPoolWorker-3] myCelery.syncAnsibleResult[8c307a9d-9bc0-4743-9d46-e1a69dc15d43]: success
[2024-09-14 18:42:34,266: ERROR/ForkPoolWorker-3] Task myCelery.syncAnsibleResult[8c307a9d-9bc0-4743-9d46-e1a69dc15d43] raised unexpected: AttributeError("'QuerySet' object has no attribute 'CeleryID'")
Traceback (most recent call last):
  File "/workspace/Python/py3/lib/python3.8/site-packages/celery/app/trace.py", line 385, in trace_task
    R = retval = fun(*args, **kwargs)
  File "/workspace/Python/py3/lib/python3.8/site-packages/celery/app/trace.py", line 648, in __protected_call__
    return self.run(*args, **kwargs)
  File "/workspace/Python/ansible_ui/myCelery.py", line 77, in syncAnsibleResult
    ct = a.get('celery-task-meta-%s' % at.CeleryID).decode()
AttributeError: 'QuerySet' object has no attribute 'CeleryID'
[2024-09-14 18:50:35,247: INFO/MainProcess] Connected to redis://127.0.0.1:6379/3
[2024-09-14 18:50:35,253: INFO/MainProcess] mingle: searching for neighbors
[2024-09-14 18:50:36,008: INFO/MainProcess] Connected to redis://127.0.0.1:6379/3
[2024-09-14 18:50:36,020: INFO/MainProcess] mingle: searching for neighbors
[2024-09-14 18:50:36,315: INFO/MainProcess] mingle: all alone
[2024-09-14 18:50:36,324: WARNING/MainProcess] /workspace/Python/py3/lib/python3.8/site-packages/celery/fixups/django.py:202: UserWarning: Using settings.DEBUG leads to a memory leak, never use this setting in production environments!
  warnings.warn('Using settings.DEBUG leads to a memory leak, never '
[2024-09-14 18:50:36,324: INFO/MainProcess] celery1@ws-beejpv-0 ready.
[2024-09-14 18:50:36,571: INFO/MainProcess] Connected to redis://127.0.0.1:6379/3
[2024-09-14 18:50:36,577: INFO/MainProcess] mingle: searching for neighbors
[2024-09-14 18:50:36,588: INFO/MainProcess] sync with celery3@ws-beejpv-0
[2024-09-14 18:50:37,033: INFO/MainProcess] mingle: all alone
[2024-09-14 18:50:37,040: WARNING/MainProcess] /workspace/Python/py3/lib/python3.8/site-packages/celery/fixups/django.py:202: UserWarning: Using settings.DEBUG leads to a memory leak, never use this setting in production environments!
  warnings.warn('Using settings.DEBUG leads to a memory leak, never '
[2024-09-14 18:50:37,041: INFO/MainProcess] celery2@ws-beejpv-0 ready.
[2024-09-14 18:50:37,591: INFO/MainProcess] mingle: sync with 1 nodes
[2024-09-14 18:50:37,591: INFO/MainProcess] mingle: sync complete
[2024-09-14 18:50:37,599: WARNING/MainProcess] /workspace/Python/py3/lib/python3.8/site-packages/celery/fixups/django.py:202: UserWarning: Using settings.DEBUG leads to a memory leak, never use this setting in production environments!
  warnings.warn('Using settings.DEBUG leads to a memory leak, never '
[2024-09-14 18:50:37,599: INFO/MainProcess] celery3@ws-beejpv-0 ready.
[2024-09-14 18:52:06,445: INFO/MainProcess] Connected to redis://127.0.0.1:6379/3
[2024-09-14 18:52:06,453: INFO/MainProcess] mingle: searching for neighbors
[2024-09-14 18:52:06,961: INFO/MainProcess] Connected to redis://127.0.0.1:6379/3
[2024-09-14 18:52:06,967: INFO/MainProcess] mingle: searching for neighbors
[2024-09-14 18:52:07,449: INFO/MainProcess] Connected to redis://127.0.0.1:6379/3
[2024-09-14 18:52:07,455: INFO/MainProcess] mingle: searching for neighbors
[2024-09-14 18:52:07,467: INFO/MainProcess] mingle: all alone
[2024-09-14 18:52:07,473: WARNING/MainProcess] /workspace/Python/py3/lib/python3.8/site-packages/celery/fixups/django.py:202: UserWarning: Using settings.DEBUG leads to a memory leak, never use this setting in production environments!
  warnings.warn('Using settings.DEBUG leads to a memory leak, never '
[2024-09-14 18:52:07,473: INFO/MainProcess] celery1@ws-beejpv-0 ready.
[2024-09-14 18:52:07,982: INFO/MainProcess] mingle: all alone
[2024-09-14 18:52:07,989: WARNING/MainProcess] /workspace/Python/py3/lib/python3.8/site-packages/celery/fixups/django.py:202: UserWarning: Using settings.DEBUG leads to a memory leak, never use this setting in production environments!
  warnings.warn('Using settings.DEBUG leads to a memory leak, never '
[2024-09-14 18:52:07,989: INFO/MainProcess] celery2@ws-beejpv-0 ready.
[2024-09-14 18:52:08,469: INFO/MainProcess] mingle: all alone
[2024-09-14 18:52:08,476: WARNING/MainProcess] /workspace/Python/py3/lib/python3.8/site-packages/celery/fixups/django.py:202: UserWarning: Using settings.DEBUG leads to a memory leak, never use this setting in production environments!
  warnings.warn('Using settings.DEBUG leads to a memory leak, never '
[2024-09-14 18:52:08,476: INFO/MainProcess] celery3@ws-beejpv-0 ready.
[2024-09-14 18:53:51,255: INFO/MainProcess] Received task: myCelery.ansiblePlayBook[800e0887-da1d-4aae-b376-2aea7b745c97]  
[2024-09-14 18:53:51,335: WARNING/ForkPoolWorker-3] PLAY [localhost]
[2024-09-14 18:53:51,371: WARNING/ForkPoolWorker-3] [34mÂÜôÂÖ•RedisÔºö{"host": "localhost", "result": {"msg": "asdasd", ......[0m
[2024-09-14 18:53:51,391: WARNING/ForkPoolWorker-3] ÊâßË°åÊàêÂäü notice from on_success
[2024-09-14 18:53:51,391: INFO/MainProcess] Received task: myCelery.syncAnsibleResult[17bd1b71-3826-4377-a537-53d0c5d02322]  
[2024-09-14 18:53:51,391: INFO/ForkPoolWorker-3] Task myCelery.ansiblePlayBook[800e0887-da1d-4aae-b376-2aea7b745c97] succeeded in 0.134745541960001s: 'success'
[2024-09-14 18:53:51,393: INFO/ForkPoolWorker-3] myCelery.syncAnsibleResult[17bd1b71-3826-4377-a537-53d0c5d02322]: success
[2024-09-14 18:53:51,814: WARNING/ForkPoolWorker-3] ÂêåÊ≠•ÁªìÊûúËá≥db: syncAnsibleResult !!!!!: parent_id: 800e0887-da1d-4aae-b376-2aea7b745c97
[2024-09-14 18:53:51,815: WARNING/ForkPoolWorker-3] Redis<ConnectionPool<Connection<host=127.0.0.1,port=6379,db=4>>>
[2024-09-14 18:53:51,815: WARNING/ForkPoolWorker-3] {'tid': 'AnsibleApiPlaybook-e1-20240914-185351'}
[2024-09-14 18:53:51,816: INFO/ForkPoolWorker-3] Task myCelery.syncAnsibleResult[17bd1b71-3826-4377-a537-53d0c5d02322] succeeded in 0.4242306500673294s: None
[2024-09-18 11:30:57,249: INFO/MainProcess] Connected to redis://127.0.0.1:6379/3
[2024-09-18 11:30:57,255: INFO/MainProcess] mingle: searching for neighbors
[2024-09-18 11:30:57,565: INFO/MainProcess] Connected to redis://127.0.0.1:6379/3
[2024-09-18 11:30:57,571: INFO/MainProcess] mingle: searching for neighbors
[2024-09-18 11:30:58,175: INFO/MainProcess] Connected to redis://127.0.0.1:6379/3
[2024-09-18 11:30:58,181: INFO/MainProcess] mingle: searching for neighbors
[2024-09-18 11:30:58,266: INFO/MainProcess] mingle: all alone
[2024-09-18 11:30:58,274: WARNING/MainProcess] /workspace/Python/py3/lib/python3.8/site-packages/celery/fixups/django.py:202: UserWarning: Using settings.DEBUG leads to a memory leak, never use this setting in production environments!
  warnings.warn('Using settings.DEBUG leads to a memory leak, never '
[2024-09-18 11:30:58,274: INFO/MainProcess] celery1@ws-beejpv-0 ready.
[2024-09-18 11:30:58,583: INFO/MainProcess] mingle: all alone
[2024-09-18 11:30:58,589: WARNING/MainProcess] /workspace/Python/py3/lib/python3.8/site-packages/celery/fixups/django.py:202: UserWarning: Using settings.DEBUG leads to a memory leak, never use this setting in production environments!
  warnings.warn('Using settings.DEBUG leads to a memory leak, never '
[2024-09-18 11:30:58,589: INFO/MainProcess] celery2@ws-beejpv-0 ready.
[2024-09-18 11:30:59,194: INFO/MainProcess] mingle: all alone
[2024-09-18 11:30:59,200: WARNING/MainProcess] /workspace/Python/py3/lib/python3.8/site-packages/celery/fixups/django.py:202: UserWarning: Using settings.DEBUG leads to a memory leak, never use this setting in production environments!
  warnings.warn('Using settings.DEBUG leads to a memory leak, never '
[2024-09-18 11:30:59,200: INFO/MainProcess] celery3@ws-beejpv-0 ready.
[2024-09-18 11:31:23,696: INFO/MainProcess] Connected to redis://127.0.0.1:6379/3
[2024-09-18 11:31:23,701: INFO/MainProcess] mingle: searching for neighbors
[2024-09-18 11:31:24,738: INFO/MainProcess] mingle: all alone
[2024-09-18 11:31:24,744: WARNING/MainProcess] /workspace/Python/py3/lib/python3.8/site-packages/celery/fixups/django.py:202: UserWarning: Using settings.DEBUG leads to a memory leak, never use this setting in production environments!
  warnings.warn('Using settings.DEBUG leads to a memory leak, never '
[2024-09-18 11:31:24,744: INFO/MainProcess] celery2@ws-beejpv-0 ready.
[2024-09-18 11:31:26,438: INFO/MainProcess] Connected to redis://127.0.0.1:6379/3
[2024-09-18 11:31:26,444: INFO/MainProcess] mingle: searching for neighbors
[2024-09-18 11:31:26,455: INFO/MainProcess] sync with celery3@ws-beejpv-0
[2024-09-18 11:31:27,459: INFO/MainProcess] mingle: sync with 1 nodes
[2024-09-18 11:31:27,459: INFO/MainProcess] mingle: sync complete
[2024-09-18 11:31:27,471: WARNING/MainProcess] /workspace/Python/py3/lib/python3.8/site-packages/celery/fixups/django.py:202: UserWarning: Using settings.DEBUG leads to a memory leak, never use this setting in production environments!
  warnings.warn('Using settings.DEBUG leads to a memory leak, never '
[2024-09-18 11:31:27,471: INFO/MainProcess] celery3@ws-beejpv-0 ready.
[2024-09-18 11:31:29,030: INFO/MainProcess] Connected to redis://127.0.0.1:6379/3
[2024-09-18 11:31:29,035: INFO/MainProcess] mingle: searching for neighbors
[2024-09-18 11:31:29,044: INFO/MainProcess] sync with celery1@ws-beejpv-0
[2024-09-18 11:31:29,044: INFO/MainProcess] sync with celery1@ws-beejpv-0
[2024-09-18 11:31:30,047: INFO/MainProcess] mingle: sync with 2 nodes
[2024-09-18 11:31:30,047: INFO/MainProcess] mingle: sync complete
[2024-09-18 11:31:30,054: WARNING/MainProcess] /workspace/Python/py3/lib/python3.8/site-packages/celery/fixups/django.py:202: UserWarning: Using settings.DEBUG leads to a memory leak, never use this setting in production environments!
  warnings.warn('Using settings.DEBUG leads to a memory leak, never '
[2024-09-18 11:31:30,054: INFO/MainProcess] celery1@ws-beejpv-0 ready.
[2024-09-18 11:50:12,992: INFO/MainProcess] Received task: myCelery.ansiblePlayBook[b60f730c-f5a3-48ae-8abc-093dd1e898d7]  
[2024-09-18 11:50:13,162: WARNING/ForkPoolWorker-3] PLAY [localhost]
[2024-09-18 11:50:13,214: WARNING/ForkPoolWorker-3] [34mÂÜôÂÖ•RedisÔºö{"host": "localhost", "result": {"msg": "The task ......[0m
[2024-09-18 11:50:13,215: WARNING/ForkPoolWorker-3] to retry, use: --limit @/root/.ansible-retry/debug.retry
[2024-09-18 11:50:13,215: INFO/ForkPoolWorker-3] 	to retry, use: --limit @/root/.ansible-retry/debug.retry

[2024-09-18 11:50:13,231: WARNING/ForkPoolWorker-3] ÊâßË°åÊàêÂäü notice from on_success
[2024-09-18 11:50:13,231: INFO/ForkPoolWorker-3] Task myCelery.ansiblePlayBook[b60f730c-f5a3-48ae-8abc-093dd1e898d7] succeeded in 0.23792044445872307s: 'success'
[2024-09-18 11:50:13,231: INFO/MainProcess] Received task: myCelery.syncAnsibleResult[73e1bf55-6fc7-4c65-8eb5-efd799594eb4]  
[2024-09-18 11:50:13,233: INFO/ForkPoolWorker-3] myCelery.syncAnsibleResult[73e1bf55-6fc7-4c65-8eb5-efd799594eb4]: success
[2024-09-18 11:50:13,616: WARNING/ForkPoolWorker-3] ÂêåÊ≠•ÁªìÊûúËá≥db: syncAnsibleResult !!!!!: parent_id: b60f730c-f5a3-48ae-8abc-093dd1e898d7
[2024-09-18 11:50:13,617: WARNING/ForkPoolWorker-3] Redis<ConnectionPool<Connection<host=127.0.0.1,port=6379,db=4>>>
[2024-09-18 11:50:13,617: WARNING/ForkPoolWorker-3] {'tid': 'AnsibleApiPlaybook-il-20240918-115012'}
[2024-09-18 11:50:13,617: INFO/ForkPoolWorker-3] Task myCelery.syncAnsibleResult[73e1bf55-6fc7-4c65-8eb5-efd799594eb4] succeeded in 0.3850359730422497s: None
